<?xml version="1.0" encoding="UTF-8"?>
<testng-results ignored="0" total="1" passed="0" failed="1" skipped="0">
  <reporter-output>
  </reporter-output>
  <suite started-at="2023-05-20T15:48:23Z" name="Default suite" finished-at="2023-05-20T15:48:23Z" duration-ms="112">
    <groups>
    </groups>
    <test started-at="2023-05-20T15:48:23Z" name="Default test" finished-at="2023-05-20T15:48:23Z" duration-ms="112">
      <class name="pruebas.Laboratorio5_E4">
        <test-method is-config="true" signature="setUp()[pri:0, instance:pruebas.Laboratorio5_E4@d737b89]" started-at="2023-05-20T12:48:15Z" name="setUp" finished-at="2023-05-20T12:48:23Z" duration-ms="7725" status="PASS">
          <reporter-output>
          </reporter-output>
        </test-method> <!-- setUp -->
        <test-method signature="verCelda()[pri:0, instance:pruebas.Laboratorio5_E4@d737b89]" started-at="2023-05-20T12:48:23Z" name="verCelda" finished-at="2023-05-20T12:48:23Z" duration-ms="70" status="FAIL">
          <exception class="java.lang.AssertionError">
            <message>
              <![CDATA[expected [9] but found [8]]]>
            </message>
            <full-stacktrace>
              <![CDATA[java.lang.AssertionError: expected [9] but found [8]
	at org.testng.Assert.fail(Assert.java:94)
	at org.testng.Assert.failNotEquals(Assert.java:513)
	at org.testng.Assert.assertEqualsImpl(Assert.java:135)
	at org.testng.Assert.assertEquals(Assert.java:116)
	at org.testng.Assert.assertEquals(Assert.java:190)
	at org.testng.Assert.assertEquals(Assert.java:200)
	at pruebas.Laboratorio5_E4.verCelda(Laboratorio5_E4.java:34)
	at java.base/jdk.internal.reflect.NativeMethodAccessorImpl.invoke0(Native Method)
	at java.base/jdk.internal.reflect.NativeMethodAccessorImpl.invoke(NativeMethodAccessorImpl.java:77)
	at java.base/jdk.internal.reflect.DelegatingMethodAccessorImpl.invoke(DelegatingMethodAccessorImpl.java:43)
	at java.base/java.lang.reflect.Method.invoke(Method.java:568)
	at org.testng.internal.MethodInvocationHelper.invokeMethod(MethodInvocationHelper.java:104)
	at org.testng.internal.Invoker.invokeMethod(Invoker.java:645)
	at org.testng.internal.Invoker.invokeTestMethod(Invoker.java:851)
	at org.testng.internal.Invoker.invokeTestMethods(Invoker.java:1177)
	at org.testng.internal.TestMethodWorker.invokeTestMethods(TestMethodWorker.java:129)
	at org.testng.internal.TestMethodWorker.run(TestMethodWorker.java:112)
	at org.testng.TestRunner.privateRun(TestRunner.java:756)
	at org.testng.TestRunner.run(TestRunner.java:610)
	at org.testng.SuiteRunner.runTest(SuiteRunner.java:387)
	at org.testng.SuiteRunner.runSequentially(SuiteRunner.java:382)
	at org.testng.SuiteRunner.privateRun(SuiteRunner.java:340)
	at org.testng.SuiteRunner.run(SuiteRunner.java:289)
	at org.testng.SuiteRunnerWorker.runSuite(SuiteRunnerWorker.java:52)
	at org.testng.SuiteRunnerWorker.run(SuiteRunnerWorker.java:86)
	at org.testng.TestNG.runSuitesSequentially(TestNG.java:1293)
	at org.testng.TestNG.runSuitesLocally(TestNG.java:1218)
	at org.testng.TestNG.runSuites(TestNG.java:1133)
	at org.testng.TestNG.run(TestNG.java:1104)
	at org.testng.remote.AbstractRemoteTestNG.run(AbstractRemoteTestNG.java:115)
	at org.testng.remote.RemoteTestNG.initAndRun(RemoteTestNG.java:251)
	at org.testng.remote.RemoteTestNG.main(RemoteTestNG.java:77)
]]>
            </full-stacktrace>
          </exception> <!-- java.lang.AssertionError -->
          <reporter-output>
          </reporter-output>
        </test-method> <!-- verCelda -->
        <test-method is-config="true" signature="cerrar()[pri:0, instance:pruebas.Laboratorio5_E4@d737b89]" started-at="2023-05-20T12:48:23Z" name="cerrar" finished-at="2023-05-20T12:48:24Z" duration-ms="770" status="PASS">
          <reporter-output>
          </reporter-output>
        </test-method> <!-- cerrar -->
      </class> <!-- pruebas.Laboratorio5_E4 -->
    </test> <!-- Default test -->
  </suite> <!-- Default suite -->
</testng-results>
